Workbook

Sheet Read Me
B1: Rockland & Hanover Drop-Off Target List
B2: In-person prospecting universe for 5 Point Technology. Built August 24, 2026.
B4: What this is
B5: 104 businesses within about 15 minutes of Rockland and Hanover, MA: Rockland, Hanover, Norwell,
B6: Pembroke, Whitman, Abington, Hanson, plus one flagged nearby HQ. Sized roughly 20 to 500 on site,
B7: with a few larger local anchors kept in on purpose. Grouped into drivable half-day routes.
B9: Tiers
B10: A | C10: Bullseye. Fits the 5PT ICP: 50 to 500 staff or a compliance heavy vertical, decision maker on site.
B11: B | C11: Strong fit. Typically 25 to 100 staff, real office and operations, worth a stop on every route pass.
B12: C | C12: Opportunistic. Branches of larger companies, big local anchors, trades and dealers. Visit when on route.
B14: Counts
B15: Total targets | C15: =COUNTA('Target List'!$C$2:$C$105) -> 104
B16: Tier A | C16: =COUNTIF('Target List'!$A$2:$A$105,"A") -> 29
B17: Tier B | C17: =COUNTIF('Target List'!$A$2:$A$105,"B") -> 45
B18: Tier C | C18: =COUNTIF('Target List'!$A$2:$A$105,"C") -> 30
B19: With named IT contact | C19: =COUNTIF('Target List'!$H$2:$H$105,"?*") -> 36
B20: With named owner/exec | C20: =COUNTIF('Target List'!$I$2:$I$105,"?*") -> 77
B22: Your columns (highlighted yellow in the Target List)
B23: Status, Visit date, and Next step are yours to fill after each stop. Status has a dropdown. Example:
C24: Status | D24: Visit date | E24: Next step
C25: Met DM | D25: 09/03/26 | E25: Call booked Tue 9/9 9am w/ Anthony
B27: Sources and caveats
B28: Company and contact data: ZoomInfo, pulled and enriched 08/24/2026. Flagged rows spot checked on the web.
B29: Employee counts are ZoomInfo estimates and often span all of a company's locations, not just this address.
B30: Excluded on purpose: town government, public schools, police, restaurants and salons, other IT providers,
B31: and listings that were defunct or wrongly geocoded. Contact names age fast: confirm at the front desk.
B32: The Parent / ownership column flags branches and acquisitions where IT may be decided elsewhere.

Sheet Target List
A1: Tier | B1: Route | C1: Company | D1: What they do | E1: Street (map link) | F1: Town | G1: Phone | H1: IT contact (ask for) | I1: Owner / exec | J1: Door opener | K1: Emp est | L1: Rev $M | M1: Founded | N1: Parent / ownership | O1: Website | P1: Notes | Q1: Status | R1: Visit date | S1: Next step | T1: ZIP | U1: ZoomInfo ID
A2: A | B2: R1 Rockland Exit14/Ledgewood | C2: Cutter Associates | D2: Investment management research and consulting | E2: 1050 Hingham St, Fl 1 | F2: Rockland | G2: (339) 469-0600 | I2: Cindy Castellano (Chief Executive Officer) | J2: Financial services firm handling asset manager data. Lead with security posture and M365 hardening. | K2: 97 | L2: 26372000 | M2: 1998 | N2: Nomura Research Institute | O2: cutterassociates.com | P2: Owned by Nomura Research Institute since 2022. Local office still runs day to day here. Hybrid workforce. | Q2: Not visited | T2: 02370 | U2: 19993081
A3: A | B3: R1 Rockland Exit14/Ledgewood | C3: FINTRX | D3: Family office and RIA data platform (SaaS) | E3: 40 Reservoir Park Dr, Ste A | F3: Rockland | G3: (617) 517-0789 | H3: Bruno Bonifacini (Software Developer & Security Integrations Specialist) | I3: Dennis Caulfield (Chief Product & Data Officer) | J3: Growing fintech with SOC 2 expectations from clients. Lead with co-managed security and compliance. | K3: 85 | L3: 17855000 | M3: 2014 | O3: fintrx.com | P3: Has developers but likely thin IT ops. Good co-managed fit. Fast growth company. | Q3: Not visited | T3: 02370 | U3: 461888001
A4: B | B4: R1 Rockland Exit14/Ledgewood | C4: The Catered Affair | D4: High end catering and events company, HQ | E4: 70 Ledgewood Pl | F4: Rockland | G4: (781) 982-9333 | H4: Gare Reid (Manager, Systems Integration) | I4: Holly Safford (Founder & President) | J4: Seasonal staff surges and POS plus office systems. Lead with device turnaround and help desk overflow. | K4: 320 | L4: 58320000 | M4: 1980 | O4: thecateredaffair.com | P4: Runs venues across Boston area from this HQ. Employee count includes event staff. | Q4: Not visited | T4: 02370 | U4: 7012563
A5: B | B5: R1 Rockland Exit14/Ledgewood | C5: ControlPoint Technologies | D5: Electrical engineering and utility consulting | E5: 200 Ledgewood Pl, Ste 300 | F5: Rockland | G5: (781) 261-9666 | H5: Adam Houghton (Director, System Planning) | I5: Jeffrey Flint (President) | J5: Engineers with CAD workstations and utility client data. Lead with backup, DR and project file uptime. | K5: 74 | L5: 9809000 | M5: 1999 | O5: cpteng.com | P5: Same building as Food Tech. Two stops, one parking lot. | Q5: Not visited | T5: 02370 | U5: 9470939
A6: B | B6: R1 Rockland Exit14/Ledgewood | C6: Burke & Associates CPAs | D6: CPA and advisory firm | E6: 300 Ledgewood Pl, Ste 300 | F6: Rockland | G6: (781) 741-8887 | J6: CPA firms must have a written security plan under FTC Safeguards. Ask who maintains their WISP. | K6: 27 | L6: 5377000 | M6: 1997 | O6: burkeandassoc.com | P6: Tax season uptime is everything. Best visited May through November. | Q6: Not visited | T6: 02370 | U6: 44551959
A7: C | B7: R1 Rockland Exit14/Ledgewood | C7: EMD Serono | D7: Biopharma R&D campus (Merck KGaA) | E7: 1 Technology Pl | F7: Rockland | G7: (800) 283-8088 | H7: Richard Feldman (Vice President, Trade Product Security & Done) | J7: Enterprise IT runs from global. Networking value only. Do not cold walk in past security. | K7: 2105 | L7: 758493000 | M7: 1981 | N7: Merck KGaA | O7: emdserono.com | P7: Long shot. Better reached through events or referrals than a lobby visit. | Q7: Not visited | T7: 02370 | U7: 92047565
A8: C | B8: R1 Rockland Exit14/Ledgewood | C8: Food Tech | D8: Design build firm for food processing facilities | E8: 200 Ledgewood Pl, Ste 200 | F8: Rockland | G8: (781) 261-9700 | H8: Leanda Karunia (Manager, Process & System Cum PA) | I8: Jonathan Kohan (President) | J8: Project teams in the field need reliable laptops and file access. Lead with device management. | K8: 40 | L8: 3149000 | M8: 2008 | N8: EMCOR Group | O8: foodtech.com | P8: EMCOR subsidiary, so corporate IT may exist. Local office worth a walk in while next door. | Q8: Not visited | T8: 02370 | U8: 27002672
A9: A | B9: R2 Rockland Weymouth/Union | C9: Rockland Federal Credit Union | D9: Credit union, main office | E9: 241 Union St | F9: Rockland | G9: (781) 878-0232 | H9: Mark Federico (Chief Information Officer) | I9: Kristin VanBeek (Chief Executive Officer & President) | J9: NCUA exams and vendor management pressure. Lead with vCISO, compliance alignment and MDR. | K9: 297 | L9: 73741000 | M9: 1922 | O9: rfcu.com | P9: Has internal IT led by a senior VP. Co-managed and security services angle, not full outsource. | Q9: Not visited | T9: 02370 | U9: 59785848
A10: A | B10: R2 Rockland Weymouth/Union | C10: UPPAbaby | D10: Premium stroller and car seat brand, global HQ | E10: 276 Weymouth St | F10: Rockland | G10: (781) 413-3000 | H10: Darrell Van Meter (Director, Information Technology) | I10: Bob Monahan (Chief Executive Officer & Co-Founder) | J10: Consumer brand with e-commerce, EDI and product data to protect. Lead with security and uptime. | K10: 136 | L10: 21613000 | M10: 2006 | O10: uppababy.com | P10: Flagship local HQ. CPSC regulated products mean documentation and systems matter. | Q10: Not visited | T10: 02370 | U10: 353910475
A11: A | B11: R2 Rockland Weymouth/Union | C11: Polymer Corporation | D11: Custom plastics and thermoforming manufacturer | E11: 180 Pleasant St | F11: Rockland | G11: (781) 871-4606 | H11: Ashwani Sharma (System Engineer) | I11: Jim Ryan (President) | J11: 100 person manufacturer, likely 0 to 2 IT staff. Lead with co-managed support and plant uptime. | K11: 103 | L11: 26997000 | M11: 1979 | O11: polymercorporation.com | P11: Classic ICP manufacturer. Strong first stop. | Q11: Not visited | T11: 02370 | U11: 343688307
A12: A | B12: R2 Rockland Weymouth/Union | C12: Briggs Engineering | D12: Civil and structural engineering, survey | E12: 100 Weymouth St, Ste C2 | F12: Rockland | G12: (781) 871-6040 | I12: Sean Skorohod (Testing Services President & Director) | J12: CAD and survey data with municipal clients. Lead with backup, DR and file server performance. | K12: 80 | L12: 30145000 | M12: 1958 | O12: briggsengineering.com | P12: Same complex as Bendon Gear. Two stops, one lot. | Q12: Not visited | T12: 02370 | U12: 17159799
A13: A | B13: R2 Rockland Weymouth/Union | C13: National Coating | D13: Coated fabrics and technical textiles manufacturer | E13: 105 Industrial Way | F13: Rockland | G13: (800) 979-9332 | J13: Production scheduling and quality systems on aging infrastructure is common here. Ask about uptime. | K13: 48 | L13: 13780000 | M13: 1977 | O13: natcoat.com | Q13: Not visited | T13: 02370 | U13: 353777346
A14: B | B14: R2 Rockland Weymouth/Union | C14: K5 Corporation | D14: Utility and civil construction contractor | E14: 9 Rockview Way, Ste B | F14: Rockland | G14: (781) 982-9229 | I14: Ronald Beaudoin (Chief Executive Officer) | J14: Contractors are prime wire fraud targets. Lead with email security and payment fraud protection. | K14: 104 | L14: 24829000 | M14: 1982 | O14: k5corporation.com | P14: Next door to Commonwealth Building Systems. | Q14: Not visited | T14: 02370 | U14: 344267938
A15: B | B15: R2 Rockland Weymouth/Union | C15: George T. Wilkinson | D15: Commercial HVAC service and mechanical contractor | E15: 405 VFW Dr, Ste 1 | F15: Rockland | G15: (781) 335-2622 | I15: Geoffrey Wilkinson (Chief Executive Officer) | J15: Dispatch, service software and field devices. Lead with help desk and device management. | K15: 68 | L15: 15840000 | M15: 1951 | O15: gtwilkinson.com | Q15: Not visited | T15: 02370 | U15: 48400778
A16: B | B16: R2 Rockland Weymouth/Union | C16: Commonwealth Building Systems | D16: Drywall and framing subcontractor | E16: 17 Rockview Way | F16: Rockland | G16: (781) 792-0032 | J16: Estimating and project files plus field crews. Lead with backup and email fraud protection. | K16: 60 | L16: 13390000 | M16: 2004 | O16: commonwealthbuildingsystems.com | P16: Next door to K5. Pair the stops. | Q16: Not visited | T16: 02370 | U16: 352266165
A17: B | B17: R2 Rockland Weymouth/Union | C17: Bendon Gear & Machine | D17: Precision gear and machine shop (defense work) | E17: 100 Weymouth St, Ste A1 | F17: Rockland | G17: (781) 878-8100 | I17: S. Belezos (Founder and Chief Executive Officer) | J17: Defense suppliers face CMMC requirements. Ask how they are handling CMMC and NIST 800-171. | K17: 25 | L17: 6443000 | M17: 1966 | O17: bendongear.com | P17: ITAR and CMMC pressure is a strong door opener for machine shops. | Q17: Not visited | T17: 02370 | U17: 7965364
A18: B | B18: R2 Rockland Weymouth/Union | C18: Alletess Medical Laboratory | D18: Clinical allergy and immunology lab | E18: 14 Howard St | F18: Rockland | G18: (800) 225-5404 | H18: John Connelly (IT Specialist) | I18: Mark McDonough (Chief Executive Officer) | J18: CLIA lab with PHI. Lead with HIPAA risk assessment and lab system uptime. | K18: 25 | L18: 7713000 | M18: 1980 | O18: foodallergy.com | Q18: Not visited | T18: 02370 | U18: 4066062
A19: C | B19: R2 Rockland Weymouth/Union | C19: Rockland Trust (Independent Bank Corp) | D19: Commercial bank, corporate offices | E19: 288 Union St | F19: Rockland | G19: (508) 732-7072 | H19: Dave Marsh (Interim Chief Information Officer) | J19: Enterprise bank with a full IT department. Networking and events only. | K19: 2294 | L19: 948692000 | M19: 1907 | N19: Independent Bank Corp | O19: rocklandtrust.com | P19: Long shot. Do not cold walk in. Useful for community sponsorship visibility. | Q19: Not visited | T19: 02370 | U19: 59785811
A20: C | B20: R2 Rockland Weymouth/Union | C20: United A/C, Heating & Refrigeration | D20: Commercial HVAC and refrigeration contractor | E20: 333 Weymouth St | F20: Rockland | G20: (781) 871-1060 | I20: Thomas Scolaro (President) | J20: Field techs on mobile devices and dispatch software. Lead with help desk and device management. | K20: 91 | L20: 2576000 | M20: 1985 | O20: united-hvac.com | P20: Employee count may include field crews. | Q20: Not visited | T20: 02370 | U20: 353591703
A21: C | B21: R2 Rockland Weymouth/Union | C21: Green Environmental | D21: Environmental testing and consulting | E21: 296 Weymouth St, Ste C | F21: Rockland | G21: (617) 479-0550 | I21: Donnie Green (President) | J21: Lab data and client reports need retention and backup. Lead with data protection. | K21: 30 | L21: 5078000 | M21: 1986 | O21: greenenvironmental.com | Q21: Not visited | T21: 02370 | U21: 29426949
A22: C | B22: R2 Rockland Weymouth/Union | C22: OneScience | D22: Scientific staffing and lab services | E22: 222 Weymouth St, Ste 2 | F22: Rockland | G22: (508) 930-1270 | J22: Placement records and client portals. Lead with M365 security and help desk. | K22: 30 | L22: 6242000 | M22: 1999 | O22: onescience.com | Q22: Not visited | T22: 02370 | U22: 50397914
A23: C | B23: R2 Rockland Weymouth/Union | C23: MIJA | D23: Pressure gauge and sensor manufacturer | E23: 11 Commerce Rd, Ste C | F23: Rockland | G23: (781) 871-5750 | I23: James Sommerio (President) | J23: Manufacturer with fire safety OEM customers. Lead with production uptime and email security. | K23: 29 | L23: 5180000 | M23: 1972 | N23: Valcom / Keltron | O23: mija.com | P23: Acquired by Keltron. Confirm who owns IT decisions locally. | Q23: Not visited | T23: 02370 | U23: 51856559
A24: C | B24: R2 Rockland Weymouth/Union | C24: RuggedMade | D24: Log splitters and outdoor power equipment, e-commerce | E24: 7 Market St | F24: Rockland | G24: (855) 878-4433 | I24: Jared Malarsky (President) | J24: E-commerce ops and warehouse systems. Lead with uptime and endpoint security. | K24: 24 | L24: 6200000 | M24: 2007 | O24: ruggedmade.com | Q24: Not visited | T24: 02370 | U24: 363680524
A25: A | B25: N1 Norwell Accord Park | C25: Avedis Zildjian Company | D25: Cymbal and drumstick maker, global HQ and factory | E25: 22 Longwater Dr | F25: Norwell | G25: (781) 871-2200 | H25: James Clifford (Senior Director, Information Technology) | I25: Thomas Young (Senior Vice President, Chief Financial Officer and Treasurer) | J25: 400 year old brand with modern e-commerce and a factory floor. Lead with plant uptime and security. | K25: 286 | L25: 32828000 | M25: 1929 | O25: zildjian.com | P25: Vic Firth is part of Zildjian, same campus. Iconic account for local proof. | Q25: Not visited | T25: 02061 | U25: 8996860
A26: A | B26: N1 Norwell Accord Park | C26: Radius Financial Group | D26: Mortgage lender, HQ | E26: 600 Longwater Dr, Ste 107 | F26: Norwell | G26: (877) 223-4800 | H26: Jake Gent (IT Support Specialist) | I26: David O'Connor (Chief Technology Officer) | J26: GLBA safeguards and loan file security. Lead with compliance, MDR and endpoint management. | K26: 281 | L26: 11835000 | M26: 1999 | O26: radiusgrp.com | P26: Same building as Miniter Group, different suite. Pair the stops. | Q26: Not visited | T26: 02061 | U26: 371618282
A27: A | B27: N1 Norwell Accord Park | C27: NVNA and Hospice (Norwell VNA) | D27: Visiting nurse association and hospice, nonprofit | E27: 120 Longwater Dr, Ste 104 | F27: Norwell | G27: (781) 659-2342 | H27: Samuel Lutz (It Help Desk Technician) | I27: Bj Snow (Chief Human Resources Officer) | J27: Clinicians in the field on mobile devices with PHI. Lead with HIPAA, device management and help desk. | K27: 262 | L27: 22797000 | M27: 1920 | O27: nvna.org | P27: Nonprofit budget cycle. EHR uptime and clinician onboarding speed are real pains. | Q27: Not visited | T27: 02061 | U27: 82658395
A28: A | B28: N1 Norwell Accord Park | C28: DIH Holding US (Hocoma) | D28: Rehab robotics and medtech, US HQ | E28: 77 Accord Park Dr, Ste D1 | F28: Norwell | G28: (617) 871-2101 | H28: Haile Mitiku (Manager, Information Technology) | I28: Jason Chen (Chief Executive Officer & Chairman) | J28: Public medtech company with FDA documentation needs. Lead with compliance ready IT and security. | K28: 200 | L28: 69573000 | M28: 2021 | O28: dih.com | P28: NASDAQ listed. Hocoma brand runs from same office. | Q28: Not visited | T28: 02061 | U28: 481121880
A29: A | B29: N1 Norwell Accord Park | C29: Miniter Group | D29: Lender placed insurance and insurtech | E29: 600 Longwater Dr, Ste 301 | F29: Norwell | G29: (800) 646-4837 | H29: Wayne Brantley (Chief Information Officer) | I29: Julianne Gilpin (President & Chief Executive Officer) | J29: Insurance data plus bank clients means audits. Lead with SOC 2 support and security posture. | K29: 120 | L29: 71702000 | M29: 1970 | O29: miniter.com | P29: Same building as Radius. Two ICP financial accounts in one stop. | Q29: Not visited | T29: 02061 | U29: 25117527
A30: A | B30: N1 Norwell Accord Park | C30: Snow & Jones | D30: Plumbing and HVAC wholesale distributor, HQ | E30: 85 Accord Park Dr | F30: Norwell | G30: (781) 878-3312 | I30: Danielle Jones (President) | J30: Multi branch distributor on one ERP. Lead with branch connectivity, uptime and ransomware defense. | K30: 90 | L30: 14844000 | M30: 1952 | O30: snowandjones.com | P30: 7 locations run from here. | Q30: Not visited | T30: 02061 | U30: 93767622
A31: A | B31: N1 Norwell Accord Park | C31: Airxchange | D31: Energy recovery ventilation components manufacturer | E31: 85 Longwater Dr | F31: Rockland | G31: (781) 871-4816 | I31: Randall Steele (President & Chief Executive Officer) | J31: OEM manufacturer with lean office staff. Lead with co-managed IT and production uptime. | K31: 70 | L31: 21533000 | M31: 1981 | O31: airxchange.com | P31: Rockland address but sits in the Accord Park corridor. Route with Norwell stops. | Q31: Not visited | T31: 02370 | U31: 2935868
A32: B | B32: N1 Norwell Accord Park | C32: Alternatives ABA | D32: ABA therapy provider | E32: 76 Accord Park Dr | F32: Norwell | G32: (781) 923-0900 | J32: Therapists documenting sessions on tablets. Lead with HIPAA, MDM and fast clinician onboarding. | K32: 199 | L32: 16725000 | M32: 2015 | O32: alternativesaba.com | P32: ABA groups grow fast and outgrow their IT. | Q32: Not visited | T32: 02061 | U32: 397516336
A33: B | B33: N1 Norwell Accord Park | C33: North River Home Care | D33: Private home care agency | E33: 275 Longwater Dr | F33: Norwell | G33: (781) 352-0939 | I33: Heather Kenney (Owner) | J33: Caregiver scheduling and PHI on personal devices. Lead with HIPAA and mobile device management. | K33: 146 | L33: 16932000 | M33: 1975 | O33: northriverhc.com | Q33: Not visited | T33: 02061 | U33: 347309462
A34: B | B34: N1 Norwell Accord Park | C34: Radio Solutions | D34: Two way radio and wireless communications dealer | E34: 55 Accord Park Dr | F34: Norwell | G34: (781) 561-3000 | H34: Matthew Dalton (Lead System Engineer) | I34: Admir Surkovic (President, Chief Executive Officer) | J34: Tech adjacent but not an MSP. Lead with M365, security and back office systems. | K34: 58 | L34: 12007000 | M34: 1998 | O34: radiosolutionsinc.com | P34: Possible referral partner too. They see every public safety and facilities buyer locally. | Q34: Not visited | T34: 02061 | U34: 354245370
A35: B | B35: N1 Norwell Accord Park | C35: TryAngle Foods | D35: Food distribution and provisions | E35: 17 Accord Park Dr, Ste 202 | F35: Norwell | G35: (781) 871-6969 | I35: Doug Vonlderstein (Founder) | J35: Orders, routing and invoicing systems. Lead with uptime and email fraud protection. | K35: 49 | L35: 9752000 | M35: 1977 | O35: tryanglefoods.com | Q35: Not visited | T35: 02061 | U35: 126845033
A36: B | B36: N1 Norwell Accord Park | C36: Blue Bear Plumbing, Heating & Air | D36: Residential home services, fast growing | E36: 300 Longwater Dr | F36: Norwell | G36: (781) 531-8227 | I36: Christopher Murphy (Owner) | J36: Fast growth home services firm. Lead with scaling help desk, dispatch uptime and onboarding techs. | K36: 34 | L36: 1166000 | M36: 2017 | O36: bluebearplumbing.com | P36: PE style growth playbook. Headcount likely higher than listed. | Q36: Not visited | T36: 02061 | U36: 451726485
A37: B | B37: N1 Norwell Accord Park | C37: The Driscoll Agency | D37: Specialty insurance agency | E37: 141 Longwater Dr, Ste 203 | F37: Norwell | G37: (781) 681-6656 | I37: Sean Driscoll (Owner) | J37: Client PII and carrier portals. Lead with email security and compliance basics. | K37: 23 | L37: 7217000 | M37: 1960 | O37: driscollagency.com | Q37: Not visited | T37: 02061 | U37: 41815502
A38: C | B38: N1 Norwell Accord Park | C38: Safety-Kleen (Clean Harbors) | D38: Environmental services, corporate offices | E38: 42 Longwater Dr | F38: Norwell | G38: (800) 323-5040 | H38: Caroline Johal (Group Manager, Information Technology Enterprise Solution) | J38: Clean Harbors corporate campus. Enterprise IT. Networking only. | K38: 4300 | L38: 1514886000 | M38: 1963 | N38: Clean Harbors | O38: safety-kleen.com | P38: Long shot. Skip on drop-off routes unless door is open. | Q38: Not visited | T38: 02061 | U38: 92389930
A39: C | B39: N1 Norwell Accord Park | C39: Sullivan Tire | D39: Tire and auto service chain, corporate HQ | E39: 41 Accord Park Dr | F39: Norwell | G39: (781) 982-1550 | H39: Joshua Sweeney (Supervisor, Application & Systems Development) | J39: Large internal IT exists. Pitch co-managed burst capacity or specific projects only. | K39: 1817 | L39: 242210000 | M39: 1955 | O39: sullivantire.com | P39: Family owned, HQ here. Worth relationship building even if no quick win. | Q39: Not visited | T39: 02061 | U39: 112869812
A40: C | B40: N1 Norwell Accord Park | C40: Signet Electronic Systems | D40: Low voltage systems integrator | E40: 90 Longwater Dr | F40: Norwell | G40: (781) 871-5888 | H40: William Ainslie (Healthcare Systems Engineer) | I40: Brad Caron (President) | J40: Integrator, now Pavion owned. Treat as partner or referral source more than prospect. | K40: 160 | L40: 59128000 | M40: 1974 | N40: Pavion | O40: signetgroup.net | P40: They install AV, security and nurse call. Complementary, not competing. Coffee meeting target. | Q40: Not visited | T40: 02061 | U40: 207552767
...

Sheet Routes
A1: Drive routes
A2: Each route is a half day: 8 to 12 stops, one geography, no backtracking. Filter the Target List by the Route column, print it, go.
A4: Code | B4: Route | C4: Stops | D4: Tier A | E4: How to work it
A5: R1 | B5: Rockland: Exit 14 corridor (Hingham St, Ledgewood Pl, Reservoir Park) | C5: =COUNTIF('Target List'!$B$2:$B$105,"R1 *") -> 7 | D5: =COUNTIFS('Target List'!$B$2:$B$105,"R1 *",'Target List'!$A$2:$A$105,"A") -> 2 | E5: One exit, one loop. Start at Cutter, work the Ledgewood Pl buildings (three targets share them), end at FINTRX. EMD Serono is a drive-by; do not cold walk past security.
A6: R2 | B6: Rockland: Weymouth St / VFW Dr industrial + Union St center | C6: =COUNTIF('Target List'!$B$2:$B$105,"R2 *") -> 16 | D6: =COUNTIFS('Target List'!$B$2:$B$105,"R2 *",'Target List'!$A$2:$A$105,"A") -> 5 | E6: Best density on the list. Industrial loop first (Weymouth St, Commerce Rd, Rockview Way pairs), then Union St for the credit union. Morning route.
A7: N1 | B7: Norwell: Accord Park & Longwater Dr (Assinippi) | C7: =COUNTIF('Target List'!$B$2:$B$105,"N1 *") -> 16 | D7: =COUNTIFS('Target List'!$B$2:$B$105,"N1 *",'Target List'!$A$2:$A$105,"A") -> 7 | E7: Two connected office parks, walkable pairs everywhere. 600 Longwater alone holds Radius and Miniter. Zildjian and Snow & Jones anchor it.
A8: N2 | B8: Norwell: Rt 53 & Queen Anne's Corner (Washington St, Pond St) | C8: =COUNTIF('Target List'!$B$2:$B$105,"N2 *") -> 11 | D8: =COUNTIFS('Target List'!$B$2:$B$105,"N2 *",'Target List'!$A$2:$A$105,"A") -> 1 | E8: Straight run down Rt 53. The 80 Washington St plaza holds three targets in one parking lot. Afternoon route, clinics after 1:30.
A9: H1 | B9: Hanover: Rt 53 & Rt 139 (Washington St, Columbia Rd) | C9: =COUNTIF('Target List'!$B$2:$B$105,"H1 *") -> 8 | D9: =COUNTIFS('Target List'!$B$2:$B$105,"H1 *",'Target List'!$A$2:$A$105,"A") -> 2 | E9: Dealer row plus Cardinal Cushing campus. Jannell Ford and First Resource face each other; Homestead and Merrill share 427 Columbia Rd.
A10: H2 | B10: West Hanover industrial (Winter St, Circuit St, King St) | C10: =COUNTIF('Target List'!$B$2:$B$105,"H2 *") -> 13 | D10: =COUNTIFS('Target List'!$B$2:$B$105,"H2 *",'Target List'!$A$2:$A$105,"A") -> 6 | E10: Manufacturer heavy, go in the morning. Winter St first (Landers, SRC, Cri-Tech), then the Circuit St loop where Sturtevant and Eyesaver share a building.
A11: P1 | B11: Pembroke: Corporate Park, Riverside Dr, Schoosett St (Rt 139/53) | C11: =COUNTIF('Target List'!$B$2:$B$105,"P1 *") -> 19 | D11: =COUNTIFS('Target List'!$B$2:$B$105,"P1 *",'Target List'!$A$2:$A$105,"A") -> 4 | E11: Biggest route, split it in two if needed. Riverside Dr and Corporate Park Dr are back to back. Royal Health and RSI share 42 Winter St.
A12: W1 | B12: Whitman, Abington & Hanson | C12: =COUNTIF('Target List'!$B$2:$B$105,"W1 *") -> 13 | D12: =COUNTIFS('Target List'!$B$2:$B$105,"W1 *",'Target List'!$A$2:$A$105,"A") -> 2 | E12: Three towns, one arc. Pair the Franklin St stops in Hanson (Sullivan's, President Titanium). Call Defense Investigators before trying to visit.
A13: X1 | B13: Nearby, verify first | C13: =COUNTIF('Target List'!$B$2:$B$105,"X1 *") -> 1 | D13: =COUNTIFS('Target List'!$B$2:$B$105,"X1 *",'Target List'!$A$2:$A$105,"A") -> 0 | E13: Bay State PT HQ is in Braintree now. Call ahead, combine with a Rt 3 errand.
B15: Suggested first outing: N1 Norwell Accord Park. Highest tier A density, everything within a half mile, and Zildjian makes a story you can tell at every other door.

Sheet Drop-Off Playbook
B1: The Drop-Off Playbook
B2: You are not selling at the door. You are earning a name, a face, and permission to follow up.
B3: Every stop ends in one of three wins: two minutes with a decision maker, the decision maker's name and email from the front desk, or a warm reason to come back. Anything else is a skip, not a failure.
B5: Before you leave
B6: • Pick one route from the Routes tab and work it end to end. 8 to 12 stops fits a half day.
B7: • Print a packet per stop: one page flyer, business card, handwritten sticky note. Folder, not a box.
B8: • Match the flyer to the stop. Experts On Demand where an IT contact is listed. Managed services or the Zero-Touch device page everywhere else.
B9: • Google each company that morning. Ten seconds per stop confirms they still exist and saves a wasted drive.
B10: • Check the IT contact and Owner columns before walking in. Asking for a person by name changes the whole interaction.
B12: Timing
B13: • Tuesday through Thursday. Monday is chaos, Friday is checkout.
B14: • Manufacturers and contractors: 8:30 to 11:00. Owners are in early.
... B63: • Contact names came from a database. Confirm at the desk: asking whether [name] still runs IT is itself a fine opener.
